{
 "cells": [
  {
   "cell_type": "code",
   "execution_count": null,
   "id": "a1cf0d8b",
   "metadata": {},
   "outputs": [
    {
     "name": "stdout",
     "output_type": "stream",
     "text": [
      " * Serving Flask app '__main__'\n",
      " * Debug mode: off\n"
     ]
    },
    {
     "name": "stderr",
     "output_type": "stream",
     "text": [
      "WARNING: This is a development server. Do not use it in a production deployment. Use a production WSGI server instead.\n",
      " * Running on http://localhost:8000\n",
      "Press CTRL+C to quit\n",
      "127.0.0.1 - - [25/May/2023 00:56:05] \"GET / HTTP/1.1\" 404 -\n",
      "[2023-05-25 00:56:17,778] ERROR in app: Exception on /predict [POST]\n",
      "Traceback (most recent call last):\n",
      "  File \"C:\\Users\\hamzi\\AppData\\Local\\Temp\\ipykernel_3304\\1630042680.py\", line 33, in predict\n",
      "    predictions = model.predict(img_batch)\n",
      "  File \"C:\\Users\\hamzi\\AppData\\Local\\Programs\\Python\\Python310\\lib\\site-packages\\keras\\utils\\traceback_utils.py\", line 70, in error_handler\n",
      "    raise e.with_traceback(filtered_tb) from None\n",
      "  File \"C:\\Users\\hamzi\\AppData\\Local\\Temp\\__autograph_generated_file5psuo_p2.py\", line 15, in tf__predict_function\n",
      "    retval_ = ag__.converted_call(ag__.ld(step_function), (ag__.ld(self), ag__.ld(iterator)), None, fscope)\n",
      "ValueError: in user code:\n",
      "\n",
      "    File \"C:\\Users\\hamzi\\AppData\\Local\\Programs\\Python\\Python310\\lib\\site-packages\\keras\\engine\\training.py\", line 2169, in predict_function  *\n",
      "        return step_function(self, iterator)\n",
      "    File \"C:\\Users\\hamzi\\AppData\\Local\\Programs\\Python\\Python310\\lib\\site-packages\\keras\\engine\\training.py\", line 2155, in step_function  **\n",
      "        outputs = model.distribute_strategy.run(run_step, args=(data,))\n",
      "    File \"C:\\Users\\hamzi\\AppData\\Local\\Programs\\Python\\Python310\\lib\\site-packages\\keras\\engine\\training.py\", line 2143, in run_step  **\n",
      "        outputs = model.predict_step(data)\n",
      "    File \"C:\\Users\\hamzi\\AppData\\Local\\Programs\\Python\\Python310\\lib\\site-packages\\keras\\engine\\training.py\", line 2111, in predict_step\n",
      "        return self(x, training=False)\n",
      "    File \"C:\\Users\\hamzi\\AppData\\Local\\Programs\\Python\\Python310\\lib\\site-packages\\keras\\utils\\traceback_utils.py\", line 70, in error_handler\n",
      "        raise e.with_traceback(filtered_tb) from None\n",
      "    File \"C:\\Users\\hamzi\\AppData\\Local\\Programs\\Python\\Python310\\lib\\site-packages\\keras\\engine\\input_spec.py\", line 298, in assert_input_compatibility\n",
      "        raise ValueError(\n",
      "\n",
      "    ValueError: Input 0 of layer \"sequential_2\" is incompatible with the layer: expected shape=(None, 256, 256, 3), found shape=(None, 224, 224, 3)\n",
      "\n",
      "\n",
      "During handling of the above exception, another exception occurred:\n",
      "\n",
      "Traceback (most recent call last):\n",
      "  File \"C:\\Users\\hamzi\\AppData\\Local\\Programs\\Python\\Python310\\lib\\site-packages\\flask\\app.py\", line 2190, in wsgi_app\n",
      "    response = self.full_dispatch_request()\n",
      "  File \"C:\\Users\\hamzi\\AppData\\Local\\Programs\\Python\\Python310\\lib\\site-packages\\flask\\app.py\", line 1486, in full_dispatch_request\n",
      "    rv = self.handle_user_exception(e)\n",
      "  File \"C:\\Users\\hamzi\\AppData\\Local\\Programs\\Python\\Python310\\lib\\site-packages\\flask\\app.py\", line 1484, in full_dispatch_request\n",
      "    rv = self.dispatch_request()\n",
      "  File \"C:\\Users\\hamzi\\AppData\\Local\\Programs\\Python\\Python310\\lib\\site-packages\\flask\\app.py\", line 1469, in dispatch_request\n",
      "    return self.ensure_sync(self.view_functions[rule.endpoint])(**view_args)\n",
      "  File \"C:\\Users\\hamzi\\AppData\\Local\\Temp\\ipykernel_3304\\1630042680.py\", line 45, in predict\n",
      "    tb_str = traceback.format_exception(etype=type(e), value=e, tb=e.__traceback__)\n",
      "TypeError: format_exception() got an unexpected keyword argument 'etype'\n",
      "127.0.0.1 - - [25/May/2023 00:56:17] \"POST /predict HTTP/1.1\" 500 -\n"
     ]
    }
   ],
   "source": [
    "from flask import Flask, request, jsonify\n",
    "from PIL import Image\n",
    "import numpy as np\n",
    "import io\n",
    "import tensorflow as tf\n",
    "import traceback\n",
    "\n",
    "app = Flask(__name__)\n",
    "\n",
    "#endpoint=\"http://localhost:8501/v1/models/potatoes_model:predict\"\n",
    "model=tf.keras.models.load_model(\"model.h5\");\n",
    "\n",
    "CLASS_NAMES = [\"Healthy Wheat\", \"Leaf Rust\", \"Wheat Loose Smut\"]\n",
    "\n",
    "@app.route(\"/ping\", methods=[\"GET\"])\n",
    "def ping():\n",
    "    return \"Alive\"\n",
    "\n",
    "@app.route(\"/predict\", methods=[\"POST\"])\n",
    "def predict():\n",
    "    try:\n",
    "        if 'file' not in request.files:\n",
    "            return jsonify({'error': 'no file provided'}), 400\n",
    "\n",
    "        file = request.files['file']\n",
    "        image = Image.open(file.stream).convert(\"RGB\")\n",
    "        image = image.resize((224, 224))  \n",
    "        image_arr = np.array(image) / 255.0 \n",
    "\n",
    "        img_batch = np.expand_dims(image_arr, 0)\n",
    "\n",
    "#         Mock prediction\n",
    "        predictions = model.predict(img_batch)\n",
    "        predicted_class = CLASS_NAMES[np.argmax(predictions[0])]\n",
    "        confidence = np.max(predictions[0])\n",
    "#         predicted_class = \"mock_class\"\n",
    "#         confidence = 0.9\n",
    "        print(\"request working\")\n",
    "\n",
    "        return jsonify({\n",
    "            'class': predicted_class,\n",
    "            'confidence': float(confidence)\n",
    "        })\n",
    "    except Exception as e:\n",
    "        tb_str = traceback.format_exception(etype=type(e), value=e, tb=e.__traceback__)\n",
    "        print(\"\".join(tb_str))\n",
    "        return jsonify({'error': str(e)}), 400\n",
    "\n",
    "if __name__ == \"__main__\":\n",
    "    app.run(host='localhost', port=8000)\n"
   ]
  },
  {
   "cell_type": "code",
   "execution_count": null,
   "id": "b220c163",
   "metadata": {},
   "outputs": [],
   "source": []
  },
  {
   "cell_type": "code",
   "execution_count": null,
   "id": "4c0c6ada",
   "metadata": {},
   "outputs": [],
   "source": []
  }
 ],
 "metadata": {
  "kernelspec": {
   "display_name": "Python 3 (ipykernel)",
   "language": "python",
   "name": "python3"
  },
  "language_info": {
   "codemirror_mode": {
    "name": "ipython",
    "version": 3
   },
   "file_extension": ".py",
   "mimetype": "text/x-python",
   "name": "python",
   "nbconvert_exporter": "python",
   "pygments_lexer": "ipython3",
   "version": "3.10.11"
  }
 },
 "nbformat": 4,
 "nbformat_minor": 5
}
